<!DOCTYPE html>
<html lang="en">
    <head>
        <meta charset="UTF-8">
        <title>test</title>
        <style>
            
        </style>
    </head>
    <body>
        
    </body>
    <script>
        // 1.创造一个Promise实例
        const promise = new Promise(function(resolve, reject) {
            // ... some code

            if (/* 异步操作成功 */){
                resolve(value);
            } else {
                reject(error);
            }
        });
        // resolve函数的作用是，将Promise对象的状态从“未完成”变为“成功”（即从 pending 变为 resolved），在异步操作成功时调用，
        //并将异步操作的结果，作为参数传递出去；reject函数的作用是，将Promise对象的状态从“未完成”变为“失败”（即从 pending 变为 rejected），
        //在异步操作失败时调用，并将异步操作报出的错误，作为参数传递出去。

        // ----------------------------------------------------------------------------------------------

        // 2.Promise实例生成以后，可以用then方法分别指定resolved状态和rejected状态的回调函数。
        promise.then(function(value) {
            // success
        }, function(error) {
            // failure
        });
        // then方法可以接受两个回调函数作为参数。第一个回调函数是Promise对象的状态变为resolved时调用，
        //第二个回调函数是Promise对象的状态变为rejected时调用。其中，第二个函数是可选的，不一定要提供。
        //这两个函数都接受Promise对象传出的值作为参数。

        // ---------------------------------------------------------------------------------------------

        // 3.一个Promise对象的简单例子
        function timeout(ms) {
            return new Promise((resolve, reject) => {
                setTimeout(resolve, ms, 'done');
            });
        }

        timeout(100).then((value) => {
            console.log(value);
        });
        // 上面代码中，timeout方法返回一个Promise实例，表示一段时间以后才会发生的结果。过了指定的时间（ms参数）以后，
        //Promise实例的状态变为resolved，就会触发then方法绑定的回调函数。

        // ---------------------------------------------------------------------------------------------------

        // 4.Promise 新建后就会立即执行
        let promise = new Promise(function(resolve, reject) {
            console.log('Promise');
            resolve();
        });

        promise.then(function() {
            console.log('resolved.');
        });

        console.log('Hi!');

        // Promise
        // Hi!
        // resolved
        
        // Promise 新建后立即执行，所以首先输出的是Promise。然后，then方法指定的回调函数，将在当前脚本所有同步任务执行完才会执行，
        //所以resolved最后输出。

        // ----------------------------------------------------------------------------------------------------

        // 5.resolve函数的参数除了正常的值以外，还可能是另一个 Promise 实例
        const p1 = new Promise(function (resolve, reject) {
            // ...
        });

        const p2 = new Promise(function (resolve, reject) {
            // ...
            resolve(p1);
        })
        // 上面代码中，p1和p2都是 Promise 的实例，但是p2的resolve方法将p1作为参数，即一个异步操作的结果是返回另一个异步操作。
        //注意，这时p1的状态就会传递给p2，也就是说，p1的状态决定了p2的状态。如果p1的状态是pending，那么p2的回调函数就会等待p1的状态改变；
        //如果p1的状态已经是resolved或者rejected，那么p2的回调函数将会立刻执行。

        // --------------------------------------------------------------------------------------------------------

        // 6.
        const p1 = new Promise(function (resolve, reject) {
            setTimeout(() => reject(new Error('fail')), 3000)
        })

        const p2 = new Promise(function (resolve, reject) {
            setTimeout(() => resolve(p1), 1000)
        })

        p2
            .then(result => console.log(result))
            .catch(error => console.log(error))
        // Error: fail
        // p1是一个 Promise，3 秒之后变为rejected。p2的状态在 1 秒之后改变，resolve方法返回的是p1。由于p2返回的是另一个 Promise，
        //导致p2自己的状态无效了，由p1的状态决定p2的状态。所以，后面的then语句都变成针对后者（p1）。又过了 2 秒，p1变为rejected，
        //导致触发catch方法指定的回调函数。

        // -----------------------------------------------------------------------------------------------------------

        // 7.调用resolve或reject并不会终结 Promise 的参数函数的执行
        new Promise((resolve, reject) => {
            resolve(1);
            console.log(2);
        }).then(r => {
            console.log(r);
        });
        // 2
        // 1
        //调用resolve(1)以后，后面的console.log(2)还是会执行，并且会首先打印出来。这是因为立即 resolved 的 Promise 是在本轮事件
        //循环的末尾执行，总是晚于本轮循环的同步任务。

        // ---------------------------------------------------------------------------------------------------

        //8.
        new Promise((resolve, reject) => {
            return resolve(1);
            // 后面的语句不会执行
            console.log(2);
        })
        //一般来说，调用resolve或reject以后，Promise 的使命就完成了，后继操作应该放到then方法里面，而不应该直接写在resolve或reject的后面。
        //所以，最好在它们前面加上return语句，这样就不会有意外。

        // -----------------------------------------------------------------------------------------------------

        // 9.采用链式的then，可以指定一组按照次序调用的回调函数
        getJSON("/post/1.json").then(function(post) {
            return getJSON(post.commentURL);
        }).then(function (comments) {
            console.log("resolved: ", comments);
        }, function (err){
            console.log("rejected: ", err);
        });
        // 第一个then方法指定的回调函数，返回的是另一个Promise对象。这时，第二个then方法指定的回调函数，
        //就会等待这个新的Promise对象状态发生变化。如果变为resolved，就调用第一个回调函数，如果状态变为rejected，就调用第二个回调函数。

        // ----------------------------------------------------------------------------------------------------

        // 10.如果采用箭头函数，上面的代码可以写得更简洁。
        getJSON("/post/1.json").then(
            post => getJSON(post.commentURL)
        ).then(
            comments => console.log("resolved: ", comments),
            err => console.log("rejected: ", err)
        );

        // --------------------------------------------------------------------------------------------------

        // 11.Promise.prototype.catch方法用于指定发生错误时的回调函数。
        getJSON('/posts.json').then(function(posts) {
            // ...
        }).catch(function(error) {
            // 处理 getJSON 和 前一个回调函数运行时发生的错误
            console.log('发生错误！', error);
        });
        // getJSON方法返回一个 Promise 对象，如果该对象状态变为resolved，则会调用then方法指定的回调函数；如果异步操作抛出错误，
        //状态就会变为rejected，就会调用catch方法指定的回调函数，处理这个错误。另外，then方法指定的回调函数，
        //如果运行中抛出错误，也会被catch方法捕获。

        // -------------------------------------------------------------------------------------------------

        //11.catch方法捕获promise抛出的错误
        const promise = new Promise(function(resolve, reject) {
            throw new Error('test');
        });
        promise.catch(function(error) {
            console.log(error);
        });
        // Error: test
        // promise抛出一个错误，就被catch方法指定的回调函数捕获。注意，上面的写法与下面两种写法是等价的。

        // ---------------------------------------------------------------------------------------------------

        // 12.如果 Promise 状态已经变成resolved，再抛出错误是无效的。
        const promise = new Promise(function(resolve, reject) {
            resolve('ok');
            throw new Error('test');
        });
        promise
            .then(function(value) { console.log(value) })
            .catch(function(error) { console.log(error) });
        // ok
        // Promise 在resolve语句后面，再抛出错误，不会被捕获，等于没有抛出。因为 Promise 的状态一旦改变，就永久保持该状态，不会再变了。

        // ---------------------------------------------------------------------------------------------------

        
    </script>
</html>
